{
  "stats": {
    "suites": 0,
    "tests": 1,
    "passes": 0,
    "pending": 0,
    "failures": 1,
    "start": "2024-11-16T06:26:06.695Z",
    "end": "2024-11-16T06:26:07.299Z",
    "duration": 604,
    "testsRegistered": 1,
    "passPercent": 0,
    "pendingPercent": 0,
    "other": 0,
    "hasOther": false,
    "skipped": 0,
    "hasSkipped": false
  },
  "results": [
    {
      "uuid": "70f42685-ad35-411e-90d3-cc7b9a1c3954",
      "title": "",
      "fullFile": "cypress\\e2e\\asser2.cy.js",
      "file": "cypress\\e2e\\asser2.cy.js",
      "beforeHooks": [],
      "afterHooks": [],
      "tests": [
        {
          "title": "An uncaught error was detected outside of a test",
          "fullTitle": "An uncaught error was detected outside of a test",
          "timedOut": null,
          "duration": 445,
          "state": "failed",
          "speed": null,
          "pass": false,
          "fail": true,
          "pending": false,
          "context": null,
          "code": "throw err;",
          "err": {
            "message": "CypressError: The following error originated from your test code, not from Cypress.\n\n  > Cannot call `cy.url()` outside a running test.\n\nThis usually happens when you accidentally write commands outside an `it(...)` test.\n\nIf that is the case, just move these commands inside an `it(...)` test.\n\nCheck your test file for errors.\n\nWhen Cypress detects uncaught errors originating from your test code it will automatically fail the current test.\n\nCypress could not associate this error to any specific test.\n\nWe dynamically generated a new test to display this failure.\n\nhttps://on.cypress.io/cannot-execute-commands-outside-test",
            "estack": "CypressError: The following error originated from your test code, not from Cypress.\n\n  > Cannot call `cy.url()` outside a running test.\n\nThis usually happens when you accidentally write commands outside an `it(...)` test.\n\nIf that is the case, just move these commands inside an `it(...)` test.\n\nCheck your test file for errors.\n\nWhen Cypress detects uncaught errors originating from your test code it will automatically fail the current test.\n\nCypress could not associate this error to any specific test.\n\nWe dynamically generated a new test to display this failure.\n\nhttps://on.cypress.io/cannot-execute-commands-outside-test\n    at ensureRunnable (http://localhost:65245/__cypress/runner/cypress_runner.js:137476:58)\n    at cy.<computed> [as url] (http://localhost:65245/__cypress/runner/cypress_runner.js:138053:7)\n    at Object.create (http://localhost:65245/__cypress/runner/cypress_runner.js:160733:19)\n    at context.describe.context.context (http://localhost:65245/__cypress/runner/cypress_runner.js:160452:27)\n    at createRunnable (http://localhost:65245/__cypress/runner/cypress_runner.js:145065:31)\n    at <unknown> (http://localhost:65245/__cypress/runner/cypress_runner.js:145126:14)\n    at <unknown> (http://localhost:65245/__cypress/runner/cypress_runner.js:111653:23)\n    at tryCatcher (http://localhost:65245/__cypress/runner/cypress_runner.js:1807:23)\n    at Object.gotValue (http://localhost:65245/__cypress/runner/cypress_runner.js:6476:18)\n    at Object.gotAccum (http://localhost:65245/__cypress/runner/cypress_runner.js:6465:25)\n    at Object.tryCatcher (http://localhost:65245/__cypress/runner/cypress_runner.js:1807:23)\n    at Promise._settlePromiseFromHandler (http://localhost:65245/__cypress/runner/cypress_runner.js:1519:31)\n    at Promise._settlePromise (http://localhost:65245/__cypress/runner/cypress_runner.js:1576:18)\n    at Promise._settlePromise0 (http://localhost:65245/__cypress/runner/cypress_runner.js:1621:10)\n    at Promise._settlePromises (http://localhost:65245/__cypress/runner/cypress_runner.js:1701:18)\n    at _drainQueueStep (http://localhost:65245/__cypress/runner/cypress_runner.js:2407:12)\n    at _drainQueue (http://localhost:65245/__cypress/runner/cypress_runner.js:2400:9)\n    at Async._drainQueues (http://localhost:65245/__cypress/runner/cypress_runner.js:2416:5)\n    at Async.drainQueues (http://localhost:65245/__cypress/runner/cypress_runner.js:2286:14)",
            "diff": null
          },
          "uuid": "088acb02-7e78-4ef1-b94b-c111226adebd",
          "parentUUID": "70f42685-ad35-411e-90d3-cc7b9a1c3954",
          "isHook": false,
          "skipped": false
        }
      ],
      "suites": [],
      "passes": [],
      "failures": [
        "088acb02-7e78-4ef1-b94b-c111226adebd"
      ],
      "pending": [],
      "skipped": [],
      "duration": 445,
      "root": true,
      "rootEmpty": false,
      "_timeout": 2000
    }
  ],
  "meta": {
    "mocha": {
      "version": "7.0.1"
    },
    "mochawesome": {
      "options": {
        "quiet": false,
        "reportFilename": "mochawesome",
        "saveHtml": true,
        "saveJson": true,
        "consoleReporter": "spec",
        "useInlineDiffs": false,
        "code": true
      },
      "version": "7.1.3"
    },
    "marge": {
      "options": {
        "reportDir": "cypress/results",
        "overwrite": false,
        "html": true,
        "json": true
      },
      "version": "6.2.0"
    }
  }
}